[2020-04-01 15:53:50,210] ERROR in app: Exception on /alive [GET]
Traceback (most recent call last):
  File "/home/ajspurlo/virtualenv/firestone/3.7/lib/python3.7/site-packages/flask/app.py", line 2446, in wsgi_app
    response = self.full_dispatch_request()
  File "/home/ajspurlo/virtualenv/firestone/3.7/lib/python3.7/site-packages/flask/app.py", line 1951, in full_dispatch_request
    rv = self.handle_user_exception(e)
  File "/home/ajspurlo/virtualenv/firestone/3.7/lib/python3.7/site-packages/flask/app.py", line 1820, in handle_user_exception
    reraise(exc_type, exc_value, tb)
  File "/home/ajspurlo/virtualenv/firestone/3.7/lib/python3.7/site-packages/flask/_compat.py", line 39, in reraise
    raise value
  File "/home/ajspurlo/virtualenv/firestone/3.7/lib/python3.7/site-packages/flask/app.py", line 1949, in full_dispatch_request
    rv = self.dispatch_request()
  File "/home/ajspurlo/virtualenv/firestone/3.7/lib/python3.7/site-packages/flask/app.py", line 1935, in dispatch_request
    return self.view_functions[rule.endpoint](**req.view_args)
  File "/home/ajspurlo/firestone/app/auth/license.py", line 24, in decorator
    response = json.loads(response.text)
  File "/opt/alt/python37/lib64/python3.7/json/__init__.py", line 348, in loads
    return _default_decoder.decode(s)
  File "/opt/alt/python37/lib64/python3.7/json/decoder.py", line 337, in decode
    obj, end = self.raw_decode(s, idx=_w(s, 0).end())
  File "/opt/alt/python37/lib64/python3.7/json/decoder.py", line 355, in raw_decode
    raise JSONDecodeError("Expecting value", s, err.value) from None
json.decoder.JSONDecodeError: Expecting value: line 1 column 1 (char 0)
[2020-04-01 15:54:03,004] ERROR in app: Exception on /alive [GET]
Traceback (most recent call last):
  File "/home/ajspurlo/virtualenv/firestone/3.7/lib/python3.7/site-packages/flask/app.py", line 2446, in wsgi_app
    response = self.full_dispatch_request()
  File "/home/ajspurlo/virtualenv/firestone/3.7/lib/python3.7/site-packages/flask/app.py", line 1951, in full_dispatch_request
    rv = self.handle_user_exception(e)
  File "/home/ajspurlo/virtualenv/firestone/3.7/lib/python3.7/site-packages/flask/app.py", line 1820, in handle_user_exception
    reraise(exc_type, exc_value, tb)
  File "/home/ajspurlo/virtualenv/firestone/3.7/lib/python3.7/site-packages/flask/_compat.py", line 39, in reraise
    raise value
  File "/home/ajspurlo/virtualenv/firestone/3.7/lib/python3.7/site-packages/flask/app.py", line 1949, in full_dispatch_request
    rv = self.dispatch_request()
  File "/home/ajspurlo/virtualenv/firestone/3.7/lib/python3.7/site-packages/flask/app.py", line 1935, in dispatch_request
    return self.view_functions[rule.endpoint](**req.view_args)
  File "/home/ajspurlo/firestone/app/auth/license.py", line 24, in decorator
    response = json.loads(response.text)
  File "/opt/alt/python37/lib64/python3.7/json/__init__.py", line 348, in loads
    return _default_decoder.decode(s)
  File "/opt/alt/python37/lib64/python3.7/json/decoder.py", line 337, in decode
    obj, end = self.raw_decode(s, idx=_w(s, 0).end())
  File "/opt/alt/python37/lib64/python3.7/json/decoder.py", line 355, in raw_decode
    raise JSONDecodeError("Expecting value", s, err.value) from None
json.decoder.JSONDecodeError: Expecting value: line 1 column 1 (char 0)
[2020-04-01 15:56:32,941] ERROR in app: Exception on /alive [GET]
Traceback (most recent call last):
  File "/home/ajspurlo/virtualenv/firestone/3.7/lib/python3.7/site-packages/sqlalchemy/engine/base.py", line 1248, in _execute_context
    cursor, statement, parameters, context
  File "/home/ajspurlo/virtualenv/firestone/3.7/lib/python3.7/site-packages/sqlalchemy/engine/default.py", line 588, in do_execute
    cursor.execute(statement, parameters)
sqlite3.IntegrityError: column email is not unique

The above exception was the direct cause of the following exception:

Traceback (most recent call last):
  File "/home/ajspurlo/virtualenv/firestone/3.7/lib/python3.7/site-packages/flask/app.py", line 2446, in wsgi_app
    response = self.full_dispatch_request()
  File "/home/ajspurlo/virtualenv/firestone/3.7/lib/python3.7/site-packages/flask/app.py", line 1951, in full_dispatch_request
    rv = self.handle_user_exception(e)
  File "/home/ajspurlo/virtualenv/firestone/3.7/lib/python3.7/site-packages/flask/app.py", line 1820, in handle_user_exception
    reraise(exc_type, exc_value, tb)
  File "/home/ajspurlo/virtualenv/firestone/3.7/lib/python3.7/site-packages/flask/_compat.py", line 39, in reraise
    raise value
  File "/home/ajspurlo/virtualenv/firestone/3.7/lib/python3.7/site-packages/flask/app.py", line 1949, in full_dispatch_request
    rv = self.dispatch_request()
  File "/home/ajspurlo/virtualenv/firestone/3.7/lib/python3.7/site-packages/flask/app.py", line 1935, in dispatch_request
    return self.view_functions[rule.endpoint](**req.view_args)
  File "/home/ajspurlo/firestone/app/auth/license.py", line 44, in decorator
    db.session.commit()
  File "/home/ajspurlo/virtualenv/firestone/3.7/lib/python3.7/site-packages/sqlalchemy/orm/scoping.py", line 162, in do
    return getattr(self.registry(), name)(*args, **kwargs)
  File "/home/ajspurlo/virtualenv/firestone/3.7/lib/python3.7/site-packages/sqlalchemy/orm/session.py", line 1036, in commit
    self.transaction.commit()
  File "/home/ajspurlo/virtualenv/firestone/3.7/lib/python3.7/site-packages/sqlalchemy/orm/session.py", line 503, in commit
    self._prepare_impl()
  File "/home/ajspurlo/virtualenv/firestone/3.7/lib/python3.7/site-packages/sqlalchemy/orm/session.py", line 482, in _prepare_impl
    self.session.flush()
  File "/home/ajspurlo/virtualenv/firestone/3.7/lib/python3.7/site-packages/sqlalchemy/orm/session.py", line 2496, in flush
    self._flush(objects)
  File "/home/ajspurlo/virtualenv/firestone/3.7/lib/python3.7/site-packages/sqlalchemy/orm/session.py", line 2637, in _flush
    transaction.rollback(_capture_exception=True)
  File "/home/ajspurlo/virtualenv/firestone/3.7/lib/python3.7/site-packages/sqlalchemy/util/langhelpers.py", line 69, in __exit__
    exc_value, with_traceback=exc_tb,
  File "/home/ajspurlo/virtualenv/firestone/3.7/lib/python3.7/site-packages/sqlalchemy/util/compat.py", line 178, in raise_
    raise exception
  File "/home/ajspurlo/virtualenv/firestone/3.7/lib/python3.7/site-packages/sqlalchemy/orm/session.py", line 2597, in _flush
    flush_context.execute()
  File "/home/ajspurlo/virtualenv/firestone/3.7/lib/python3.7/site-packages/sqlalchemy/orm/unitofwork.py", line 422, in execute
    rec.execute(self)
  File "/home/ajspurlo/virtualenv/firestone/3.7/lib/python3.7/site-packages/sqlalchemy/orm/unitofwork.py", line 589, in execute
    uow,
  File "/home/ajspurlo/virtualenv/firestone/3.7/lib/python3.7/site-packages/sqlalchemy/orm/persistence.py", line 245, in save_obj
    insert,
  File "/home/ajspurlo/virtualenv/firestone/3.7/lib/python3.7/site-packages/sqlalchemy/orm/persistence.py", line 1136, in _emit_insert_statements
    statement, params
  File "/home/ajspurlo/virtualenv/firestone/3.7/lib/python3.7/site-packages/sqlalchemy/engine/base.py", line 984, in execute
    return meth(self, multiparams, params)
  File "/home/ajspurlo/virtualenv/firestone/3.7/lib/python3.7/site-packages/sqlalchemy/sql/elements.py", line 293, in _execute_on_connection
    return connection._execute_clauseelement(self, multiparams, params)
  File "/home/ajspurlo/virtualenv/firestone/3.7/lib/python3.7/site-packages/sqlalchemy/engine/base.py", line 1103, in _execute_clauseelement
    distilled_params,
  File "/home/ajspurlo/virtualenv/firestone/3.7/lib/python3.7/site-packages/sqlalchemy/engine/base.py", line 1288, in _execute_context
    e, statement, parameters, cursor, context
  File "/home/ajspurlo/virtualenv/firestone/3.7/lib/python3.7/site-packages/sqlalchemy/engine/base.py", line 1482, in _handle_dbapi_exception
    sqlalchemy_exception, with_traceback=exc_info[2], from_=e
  File "/home/ajspurlo/virtualenv/firestone/3.7/lib/python3.7/site-packages/sqlalchemy/util/compat.py", line 178, in raise_
    raise exception
  File "/home/ajspurlo/virtualenv/firestone/3.7/lib/python3.7/site-packages/sqlalchemy/engine/base.py", line 1248, in _execute_context
    cursor, statement, parameters, context
  File "/home/ajspurlo/virtualenv/firestone/3.7/lib/python3.7/site-packages/sqlalchemy/engine/default.py", line 588, in do_execute
    cursor.execute(statement, parameters)
sqlalchemy.exc.IntegrityError: (sqlite3.IntegrityError) column email is not unique
[SQL: INSERT INTO license (license_key, edition, email, order_number, country, last_seen, current_ip, all_ips) VALUES (?, ?, ?, ?, ?, ?, ?, ?)]
[parameters: ('60B21B86-1B9B4CB9-BDAE7189-C69F068B', '(GOLD Edition)', 'newfiregaming@gmail.com', 180162371, 'United States', '2020-04-01 19:56:32.923494', None, None)]
(Background on this error at: http://sqlalche.me/e/gkpj)
[2020-04-02 11:56:25,919] ERROR in app: Exception on /alive [GET]
Traceback (most recent call last):
  File "/home/ajspurlo/virtualenv/firestone/3.7/lib/python3.7/site-packages/flask/app.py", line 2446, in wsgi_app
    response = self.full_dispatch_request()
  File "/home/ajspurlo/virtualenv/firestone/3.7/lib/python3.7/site-packages/flask/app.py", line 1951, in full_dispatch_request
    rv = self.handle_user_exception(e)
  File "/home/ajspurlo/virtualenv/firestone/3.7/lib/python3.7/site-packages/flask/app.py", line 1820, in handle_user_exception
    reraise(exc_type, exc_value, tb)
  File "/home/ajspurlo/virtualenv/firestone/3.7/lib/python3.7/site-packages/flask/_compat.py", line 39, in reraise
    raise value
  File "/home/ajspurlo/virtualenv/firestone/3.7/lib/python3.7/site-packages/flask/app.py", line 1949, in full_dispatch_request
    rv = self.dispatch_request()
  File "/home/ajspurlo/virtualenv/firestone/3.7/lib/python3.7/site-packages/flask/app.py", line 1935, in dispatch_request
    return self.view_functions[rule.endpoint](**req.view_args)
  File "/home/ajspurlo/firestone/app/auth/license.py", line 24, in decorator
    response = json.loads(response.text)
  File "/opt/alt/python37/lib64/python3.7/json/__init__.py", line 348, in loads
    return _default_decoder.decode(s)
  File "/opt/alt/python37/lib64/python3.7/json/decoder.py", line 337, in decode
    obj, end = self.raw_decode(s, idx=_w(s, 0).end())
  File "/opt/alt/python37/lib64/python3.7/json/decoder.py", line 355, in raw_decode
    raise JSONDecodeError("Expecting value", s, err.value) from None
json.decoder.JSONDecodeError: Expecting value: line 1 column 1 (char 0)
[2020-04-02 11:56:36,148] ERROR in app: Exception on /alive [GET]
Traceback (most recent call last):
  File "/home/ajspurlo/virtualenv/firestone/3.7/lib/python3.7/site-packages/flask/app.py", line 2446, in wsgi_app
    response = self.full_dispatch_request()
  File "/home/ajspurlo/virtualenv/firestone/3.7/lib/python3.7/site-packages/flask/app.py", line 1951, in full_dispatch_request
    rv = self.handle_user_exception(e)
  File "/home/ajspurlo/virtualenv/firestone/3.7/lib/python3.7/site-packages/flask/app.py", line 1820, in handle_user_exception
    reraise(exc_type, exc_value, tb)
  File "/home/ajspurlo/virtualenv/firestone/3.7/lib/python3.7/site-packages/flask/_compat.py", line 39, in reraise
    raise value
  File "/home/ajspurlo/virtualenv/firestone/3.7/lib/python3.7/site-packages/flask/app.py", line 1949, in full_dispatch_request
    rv = self.dispatch_request()
  File "/home/ajspurlo/virtualenv/firestone/3.7/lib/python3.7/site-packages/flask/app.py", line 1935, in dispatch_request
    return self.view_functions[rule.endpoint](**req.view_args)
  File "/home/ajspurlo/firestone/app/auth/license.py", line 24, in decorator
    response = json.loads(response.text)
  File "/opt/alt/python37/lib64/python3.7/json/__init__.py", line 348, in loads
    return _default_decoder.decode(s)
  File "/opt/alt/python37/lib64/python3.7/json/decoder.py", line 337, in decode
    obj, end = self.raw_decode(s, idx=_w(s, 0).end())
  File "/opt/alt/python37/lib64/python3.7/json/decoder.py", line 355, in raw_decode
    raise JSONDecodeError("Expecting value", s, err.value) from None
json.decoder.JSONDecodeError: Expecting value: line 1 column 1 (char 0)
[2020-04-02 11:56:59,113] ERROR in app: Exception on /alive [GET]
Traceback (most recent call last):
  File "/home/ajspurlo/virtualenv/firestone/3.7/lib/python3.7/site-packages/flask/app.py", line 2446, in wsgi_app
    response = self.full_dispatch_request()
  File "/home/ajspurlo/virtualenv/firestone/3.7/lib/python3.7/site-packages/flask/app.py", line 1951, in full_dispatch_request
    rv = self.handle_user_exception(e)
  File "/home/ajspurlo/virtualenv/firestone/3.7/lib/python3.7/site-packages/flask/app.py", line 1820, in handle_user_exception
    reraise(exc_type, exc_value, tb)
  File "/home/ajspurlo/virtualenv/firestone/3.7/lib/python3.7/site-packages/flask/_compat.py", line 39, in reraise
    raise value
  File "/home/ajspurlo/virtualenv/firestone/3.7/lib/python3.7/site-packages/flask/app.py", line 1949, in full_dispatch_request
    rv = self.dispatch_request()
  File "/home/ajspurlo/virtualenv/firestone/3.7/lib/python3.7/site-packages/flask/app.py", line 1935, in dispatch_request
    return self.view_functions[rule.endpoint](**req.view_args)
  File "/home/ajspurlo/firestone/app/auth/license.py", line 24, in decorator
    response = json.loads(response.text)
  File "/opt/alt/python37/lib64/python3.7/json/__init__.py", line 348, in loads
    return _default_decoder.decode(s)
  File "/opt/alt/python37/lib64/python3.7/json/decoder.py", line 337, in decode
    obj, end = self.raw_decode(s, idx=_w(s, 0).end())
  File "/opt/alt/python37/lib64/python3.7/json/decoder.py", line 355, in raw_decode
    raise JSONDecodeError("Expecting value", s, err.value) from None
json.decoder.JSONDecodeError: Expecting value: line 1 column 1 (char 0)
[2020-04-02 11:57:23,165] ERROR in app: Exception on /alive [GET]
Traceback (most recent call last):
  File "/home/ajspurlo/virtualenv/firestone/3.7/lib/python3.7/site-packages/flask/app.py", line 2446, in wsgi_app
    response = self.full_dispatch_request()
  File "/home/ajspurlo/virtualenv/firestone/3.7/lib/python3.7/site-packages/flask/app.py", line 1951, in full_dispatch_request
    rv = self.handle_user_exception(e)
  File "/home/ajspurlo/virtualenv/firestone/3.7/lib/python3.7/site-packages/flask/app.py", line 1820, in handle_user_exception
    reraise(exc_type, exc_value, tb)
  File "/home/ajspurlo/virtualenv/firestone/3.7/lib/python3.7/site-packages/flask/_compat.py", line 39, in reraise
    raise value
  File "/home/ajspurlo/virtualenv/firestone/3.7/lib/python3.7/site-packages/flask/app.py", line 1949, in full_dispatch_request
    rv = self.dispatch_request()
  File "/home/ajspurlo/virtualenv/firestone/3.7/lib/python3.7/site-packages/flask/app.py", line 1935, in dispatch_request
    return self.view_functions[rule.endpoint](**req.view_args)
  File "/home/ajspurlo/firestone/app/auth/license.py", line 24, in decorator
    response = json.loads(response.text)
  File "/opt/alt/python37/lib64/python3.7/json/__init__.py", line 348, in loads
    return _default_decoder.decode(s)
  File "/opt/alt/python37/lib64/python3.7/json/decoder.py", line 337, in decode
    obj, end = self.raw_decode(s, idx=_w(s, 0).end())
  File "/opt/alt/python37/lib64/python3.7/json/decoder.py", line 355, in raw_decode
    raise JSONDecodeError("Expecting value", s, err.value) from None
json.decoder.JSONDecodeError: Expecting value: line 1 column 1 (char 0)
2020-04-02 18:43:48.326622 [1109772] Child process with pid: 1109777 was killed by signal: 15, core dump: 0
2020-04-02 18:44:00.543343 [1109772] Child process with pid: 1109898 was killed by signal: 15, core dump: 0
Traceback (most recent call last):
  File "/home/ajspurlo/firestone/passenger_wsgi.py", line 8, in <module>
    wsgi = imp.load_source('wsgi', 'firestone_api.py')
  File "/home/ajspurlo/virtualenv/firestone/3.7/lib64/python3.7/imp.py", line 171, in load_source
    module = _load(spec)
  File "<frozen importlib._bootstrap>", line 696, in _load
  File "<frozen importlib._bootstrap>", line 677, in _load_unlocked
  File "<frozen importlib._bootstrap_external>", line 728, in exec_module
  File "<frozen importlib._bootstrap>", line 219, in _call_with_frames_removed
  File "firestone_api.py", line 4, in <module>
    app = create_app()
  File "/home/ajspurlo/firestone/app/__init__.py", line 46, in create_app
    from app.admin import bp as admin_bp
  File "/home/ajspurlo/firestone/app/admin/__init__.py", line 5, in <module>
    from app.admin import routes, forms
  File "/home/ajspurlo/firestone/app/admin/routes.py", line 5, in <module>
    import markdown
ModuleNotFoundError: No module named 'markdown'
2020-04-02 18:44:26.968957 [1110148] Child process with pid: 1110155 was killed by signal: 15, core dump: 0
2020-04-02 18:44:28.943335 [1110148] Child process with pid: 1110185 was killed by signal: 15, core dump: 0
2020-04-02 18:44:55.354827 [1110148] Child process with pid: 1110476 was killed by signal: 15, core dump: 0
